<?xml version="1.0"?>
<!--
  Minimal differential-drive robot with a 2D lidar, set up for Gazebo Harmonic
  (gz-sim) via the ros_gz integration. Wheels are driven by the gz DiffDrive
  system; the lidar feeds an OccupancyGrid pipeline the pathfinding node can use.
-->
<robot name="pathfinding_bot" xmlns:xacro="http://www.ros.org/wiki/xacro">

  <xacro:property name="base_length" value="0.4"/>
  <xacro:property name="base_width" value="0.3"/>
  <xacro:property name="base_height" value="0.15"/>
  <xacro:property name="wheel_radius" value="0.08"/>
  <xacro:property name="wheel_width" value="0.04"/>
  <xacro:property name="wheel_separation" value="0.34"/>

  <link name="base_footprint"/>

  <link name="base_link">
    <visual>
      <geometry>
        <box size="${base_length} ${base_width} ${base_height}"/>
      </geometry>
      <material name="blue">
        <color rgba="0.2 0.4 0.8 1.0"/>
      </material>
    </visual>
    <collision>
      <geometry>
        <box size="${base_length} ${base_width} ${base_height}"/>
      </geometry>
    </collision>
    <inertial>
      <mass value="5.0"/>
      <inertia ixx="0.1" ixy="0.0" ixz="0.0" iyy="0.1" iyz="0.0" izz="0.1"/>
    </inertial>
  </link>

  <joint name="base_joint" type="fixed">
    <parent link="base_footprint"/>
    <child link="base_link"/>
    <origin xyz="0 0 ${wheel_radius + base_height/2}" rpy="0 0 0"/>
  </joint>

  <xacro:macro name="wheel" params="prefix y_reflect">
    <link name="${prefix}_wheel">
      <visual>
        <origin xyz="0 0 0" rpy="${pi/2} 0 0"/>
        <geometry>
          <cylinder radius="${wheel_radius}" length="${wheel_width}"/>
        </geometry>
        <material name="black">
          <color rgba="0.1 0.1 0.1 1.0"/>
        </material>
      </visual>
      <collision>
        <origin xyz="0 0 0" rpy="${pi/2} 0 0"/>
        <geometry>
          <cylinder radius="${wheel_radius}" length="${wheel_width}"/>
        </geometry>
      </collision>
      <inertial>
        <mass value="0.5"/>
        <inertia ixx="0.001" ixy="0.0" ixz="0.0" iyy="0.001" iyz="0.0" izz="0.001"/>
      </inertial>
    </link>
    <joint name="${prefix}_wheel_joint" type="continuous">
      <parent link="base_link"/>
      <child link="${prefix}_wheel"/>
      <origin xyz="0 ${y_reflect * wheel_separation/2} ${-base_height/2}" rpy="0 0 0"/>
      <axis xyz="0 1 0"/>
    </joint>
  </xacro:macro>

  <xacro:wheel prefix="left" y_reflect="1"/>
  <xacro:wheel prefix="right" y_reflect="-1"/>

  <link name="lidar_link">
    <visual>
      <geometry>
        <cylinder radius="0.04" length="0.04"/>
      </geometry>
    </visual>
    <inertial>
      <mass value="0.1"/>
      <inertia ixx="0.0001" ixy="0.0" ixz="0.0" iyy="0.0001" iyz="0.0" izz="0.0001"/>
    </inertial>
  </link>
  <joint name="lidar_joint" type="fixed">
    <parent link="base_link"/>
    <child link="lidar_link"/>
    <origin xyz="${base_length/2 - 0.05} 0 ${base_height/2 + 0.02}" rpy="0 0 0"/>
  </joint>

  <!-- Gazebo Harmonic (gz-sim) system plugins -->
  <gazebo>
    <plugin filename="gz-sim-diff-drive-system"
            name="gz::sim::systems::DiffDrive">
      <left_joint>left_wheel_joint</left_joint>
      <right_joint>right_wheel_joint</right_joint>
      <wheel_separation>${wheel_separation}</wheel_separation>
      <wheel_radius>${wheel_radius}</wheel_radius>
      <topic>cmd_vel</topic>
      <odom_topic>odom</odom_topic>
      <frame_id>odom</frame_id>
      <child_frame_id>base_footprint</child_frame_id>
      <odom_publish_frequency>30</odom_publish_frequency>
    </plugin>

    <plugin filename="gz-sim-sensors-system"
            name="gz::sim::systems::Sensors">
      <render_engine>ogre2</render_engine>
    </plugin>
  </gazebo>

  <gazebo reference="lidar_link">
    <sensor name="lidar" type="gpu_lidar">
      <topic>scan</topic>
      <update_rate>10</update_rate>
      <always_on>true</always_on>
      <visualize>true</visualize>
      <lidar>
        <scan>
          <horizontal>
            <samples>360</samples>
            <resolution>1</resolution>
            <min_angle>-3.14159</min_angle>
            <max_angle>3.14159</max_angle>
          </horizontal>
        </scan>
        <range>
          <min>0.12</min>
          <max>10.0</max>
          <resolution>0.01</resolution>
        </range>
      </lidar>
    </sensor>
  </gazebo>

</robot>
